Workbook
Name Slicer_Diabetes_Status: #N/A
Name Slicer_Weight_Status: #N/A

Sheet Customer Names
A1: Customer ID | B1: name
A2: Id1 | B2: Hawks, Ms. Kelly
A3: Id2 | B3: Lehner, Mr. Matthew D
A4: Id3 | B4: Lu, Mr. Phil
A5: Id4 | B5: Osborne, Ms. Kelsey
A6: Id5 | B6: Kadala, Ms. Kristyn
A7: Id6 | B7: Baker, Mr. Russell B.
A8: Id7 | B8: Macpherson, Mr. Scott
A9: Id8 | B9: Hallman, Mr. Stephen
A10: Id9 | B10: Moran, Mr. Patrick R.
A11: Id10 | B11: Benner, Ms. Brooke N.
A12: Id11 | B12: Fierro Vargas, Ms. Paola Andrea
... A2336: Id2335 | B2336: German, Mr. Aaron K

Sheet Medical Examinations
A1: Customer ID | B1: BMI | C1: HBA1C | D1: Heart Issues | E1: Any Transplants | F1: Cancer history | G1: NumberOfMajorSurgeries | H1: smoker
A2: Id1 | B2: 47.41 | C2: 7.47 | D2: No | E2: No | F2: No | G2: No major surgery | H2: yes
A3: Id2 | B3: 30.36 | C3: 5.77 | D3: No | E3: No | F3: No | G3: No major surgery | H3: yes
A4: Id3 | B4: 34.485 | C4: 11.87 | D4: yes | E4: No | F4: No | G4: 2 | H4: yes
A5: Id4 | B5: 38.095 | C5: 6.05 | D5: No | E5: No | F5: No | G5: No major surgery | H5: yes
A6: Id5 | B6: 35.53 | C6: 5.45 | D6: No | E6: No | F6: No | G6: No major surgery | H6: yes
A7: Id6 | B7: 32.8 | C7: 6.59 | D7: No | E7: No | F7: No | G7: No major surgery | H7: yes
A8: Id7 | B8: 36.4 | C8: 6.07 | D8: No | E8: No | F8: No | G8: No major surgery | H8: yes
A9: Id8 | B9: 36.96 | C9: 7.93 | D9: No | E9: No | F9: No | G9: 3 | H9: yes
A10: Id9 | B10: 41.14 | C10: 9.58 | D10: yes | E10: No | F10: Yes | G10: 1 | H10: yes
A11: Id10 | B11: 38.06 | C11: 10.79 | D11: No | E11: No | F11: No | G11: No major surgery | H11: yes
A12: Id11 | B12: 37.7 | C12: 5.96 | D12: yes | E12: No | F12: No | G12: 2 | H12: yes
A13: Id12 | B13: 42.13 | C13: 11.9 | D13: No | E13: No | F13: No | G13: No major surgery | H13: yes
A14: Id13 | B14: 40.92 | C14: 8.41 | D14: No | E14: No | F14: No | G14: No major surgery | H14: yes
A15: Id14 | B15: 40.565 | C15: 7.02 | D15: No | E15: No | F15: No | G15: No major surgery | H15: yes
A16: Id15 | B16: 36.385 | C16: 7.59 | D16: yes | E16: No | F16: No | G16: 2 | H16: yes
A17: Id16 | B17: 39.9 | C17: 11.32 | D17: No | E17: No | F17: No | G17: No major surgery | H17: yes
A18: Id17 | B18: 33.8 | C18: 7.67 | D18: No | E18: No | F18: No | G18: 3 | H18: yes
A19: Id18 | B19: 36.765 | C19: 7.29 | D19: yes | E19: No | F19: Yes | G19: 1 | H19: yes
A20: Id19 | B20: 36.955 | C20: 4.72 | D20: yes | E20: No | F20: No | G20: 1 | H20: yes
A21: Id20 | B21: 42.9 | C21: 11.41 | D21: No | E21: No | F21: No | G21: No major surgery | H21: yes
A22: Id21 | B22: 36.3 | C22: 11.5 | D22: yes | E22: No | F22: No | G22: 2 | H22: yes
A23: Id22 | B23: 32.2 | C23: 6.22 | D23: yes | E23: No | F23: No | G23: 2 | H23: yes
A24: Id23 | B24: 31.3 | C24: 11.38 | D24: No | E24: No | F24: No | G24: 3 | H24: yes
A25: Id24 | B25: 41.8 | C25: 7.89 | D25: yes | E25: No | F25: No | G25: 2 | H25: yes
A26: Id25 | B26: 35.09 | C26: 4.38 | D26: yes | E26: No | F26: No | G26: 2 | H26: yes
A27: Id26 | B27: 33.88 | C27: 7.01 | D27: No | E27: No | F27: No | G27: 3 | H27: yes
A28: Id27 | B28: 30.875 | C28: 11.88 | D28: No | E28: No | F28: No | G28: No major surgery | H28: yes
A29: Id28 | B29: 36.86 | C29: 5.19 | D29: yes | E29: No | F29: Yes | G29: 1 | H29: yes
A30: Id29 | B30: 35.86 | C30: 6.74 | D30: yes | E30: No | F30: No | G30: 2 | H30: yes
A31: Id30 | B31: 37.05 | C31: 8.44 | D31: No | E31: No | F31: No | G31: No major surgery | H31: yes
A32: Id31 | B32: 43.89 | C32: 8.71 | D32: No | E32: No | F32: No | G32: No major surgery | H32: yes
A33: Id32 | B33: 42.35 | C33: 5.08 | D33: yes | E33: No | F33: No | G33: No major surgery | H33: yes
A34: Id33 | B34: 31.35 | C34: 6.86 | D34: No | E34: No | F34: No | G34: No major surgery | H34: yes
A35: Id34 | B35: 47.6 | C35: 5.95 | D35: yes | E35: No | F35: No | G35: No major surgery | H35: yes
A36: Id35 | B36: 46.2 | C36: 6.09 | D36: No | E36: No | F36: Yes | G36: 1 | H36: yes
A37: Id36 | B37: 32.015 | C37: 11.75 | D37: No | E37: No | F37: No | G37: No major surgery | H37: yes
A38: Id37 | B38: 40.565 | C38: 7.37 | D38: No | E38: No | F38: No | G38: No major surgery | H38: yes
A39: Id38 | B39: 32.45 | C39: 11.91 | D39: No | E39: No | F39: No | G39: No major surgery | H39: yes
A40: Id39 | B40: 34.96 | C40: 6.52 | D40: No | E40: No | F40: No | G40: No major surgery | H40: yes
...

Sheet Hospitalisation Details
A1: Customer ID | B1: year | C1: month | D1: date | E1: children | F1: charges | G1: Hospital tier | H1: City tier | I1: State ID | J1: DATE OF BIRTH
A2: ? | B2: 2004 | C2: Nov | D2: 6 | E2: 0 | F2: 1137.01 | G2: tier - 3 | H2: tier - 1 | I2: R1013
A3: ? | B3: 1999 | C3: Jun | D3: 9 | E3: 1 | F3: 2775.19 | G3: tier - 2 | H3: tier - 1 | I3: R1012
A4: ? | B4: 1985 | C4: Dec | D4: 20 | E4: 2 | F4: 6203.9 | G4: tier - 1 | H4: tier - 2 | I4: R1012
A5: ? | B5: 2000 | C5: Oct | D5: 13 | E5: 0 | F5: 35585.58 | G5: tier - 1 | H5: tier - 2 | I5: R1011
A6: ? | B6: 1992 | C6: Oct | D6: 6 | E6: 0 | F6: 36837.47 | G6: tier - 1 | H6: tier - 2 | I6: R1011
A7: ? | B7: 1991 | C7: Nov | D7: 22 | E7: 2 | F7: 38711 | G7: tier - 1 | H7: tier - 3 | I7: R1011
A8: Id1 | B8: 1968 | C8: Oct | D8: 12 | E8: 0 | F8: 63770.43 | G8: tier - 1 | H8: tier - 3 | I8: R1013 | J8: =_xlfn.CONCAT(D8,"/",C8,"/",B8) -> 12/Oct/1968
A9: Id10 | B9: 1978 | C9: Dec | D9: 29 | E9: 0 | F9: 48885.14 | G9: tier - 1 | H9: tier - 2 | I9: R1013 | J9: =_xlfn.CONCAT(D9,"/",C9,"/",B9) -> 29/Dec/1978
A10: Id100 | B10: 1977 | C10: Jun | D10: 27 | E10: 2 | F10: 40284.38 | G10: tier - 1 | H10: tier - 3 | I10: R1012 | J10: =_xlfn.CONCAT(D10,"/",C10,"/",B10) -> 27/Jun/1977
A11: Id1000 | B11: 1989 | C11: Dec | D11: 17 | E11: 3 | F11: 11250.43 | G11: tier - 3 | H11: tier - 2 | I11: R1026 | J11: =_xlfn.CONCAT(D11,"/",C11,"/",B11) -> 17/Dec/1989
A12: Id1001 | B12: 1969 | C12: Dec | D12: 30 | E12: 2 | F12: 11244.38 | G12: tier - 3 | H12: tier - 1 | I12: R1016 | J12: =_xlfn.CONCAT(D12,"/",C12,"/",B12) -> 30/Dec/1969
A13: Id1002 | B13: 1976 | C13: Jun | D13: 28 | E13: 2 | F13: 11217.35 | G13: tier - 3 | H13: tier - 2 | I13: R1025 | J13: =_xlfn.CONCAT(D13,"/",C13,"/",B13) -> 28/Jun/1976
A14: Id1003 | B14: 1970 | C14: Jun | D14: 14 | E14: 2 | F14: 11187.66 | G14: tier - 3 | H14: tier - 2 | I14: R1012 | J14: =_xlfn.CONCAT(D14,"/",C14,"/",B14) -> 14/Jun/1970
A15: Id1004 | B15: 1972 | C15: Sep | D15: 3 | E15: 0 | F15: 11186.2 | G15: tier - 3 | H15: tier - 2 | I15: R1021 | J15: =_xlfn.CONCAT(D15,"/",C15,"/",B15) -> 3/Sep/1972
A16: Id1005 | B16: 1966 | C16: Aug | D16: 6 | E16: 0 | F16: 11165.42 | G16: tier - 3 | H16: tier - 1 | I16: R1016 | J16: =_xlfn.CONCAT(D16,"/",C16,"/",B16) -> 6/Aug/1966
A17: Id1006 | B17: 1969 | C17: Jun | D17: 25 | E17: 2 | F17: 11163.57 | G17: tier - 3 | H17: tier - 2 | I17: R1011 | J17: =_xlfn.CONCAT(D17,"/",C17,"/",B17) -> 25/Jun/1969
A18: Id1007 | B18: 1969 | C18: Nov | D18: 30 | E18: 2 | F18: 11150.78 | G18: tier - 3 | H18: tier - 2 | I18: R1011 | J18: =_xlfn.CONCAT(D18,"/",C18,"/",B18) -> 30/Nov/1969
A19: Id1008 | B19: 1980 | C19: Aug | D19: 20 | E19: 2 | F19: 11103.33 | G19: tier - 3 | H19: tier - 1 | I19: R1021 | J19: =_xlfn.CONCAT(D19,"/",C19,"/",B19) -> 20/Aug/1980
... A326: Id1285 | B326: 1975 | C326: Aug | D326: 6 | E326: 1 | F326: 8551.35 | G326: tier - 2 | H326: tier - 2 | I326: R1011 | J326: =_xlfn.CONCAT(D326,"/",C326,"/",B326) -> 6/Aug/1975
A327: Id1286 | B327: ? | C327: Dec | D327: 12 | E327: 1 | F327: 8547.69 | G327: tier - 2 | H327: tier - 1 | I327: R1013 | J327: =_xlfn.CONCAT(D327,"/",C327,"/",B327) -> 12/Dec/?
A328: Id1287 | B328: 1975 | C328: Nov | D328: 6 | E328: 1 | F328: 8539.67 | G328: tier - 2 | H328: tier - 3 | I328: R1011 | J328: =_xlfn.CONCAT(D328,"/",C328,"/",B328) -> 6/Nov/1975
A329: Id1288 | B329: 1981 | C329: Dec | D329: 27 | E329: 3 | F329: 8538.29 | G329: tier - 2 | H329: tier - 3 | I329: R1024 | J329: =_xlfn.CONCAT(D329,"/",C329,"/",B329) -> 27/Dec/1981
A330: Id1289 | B330: ? | C330: Jul | D330: 24 | E330: 0 | F330: 8534.67 | G330: tier - 2 | H330: tier - 3 | I330: R1024 | J330: =_xlfn.CONCAT(D330,"/",C330,"/",B330) -> 24/Jul/?
A331: Id129 | B331: 1985 | C331: Sep | D331: 20 | E331: 1 | F331: 39047.29 | G331: tier - 1 | H331: tier - 3 | I331: R1017 | J331: =_xlfn.CONCAT(D331,"/",C331,"/",B331) -> 20/Sep/1985
A332: Id1290 | B332: 1977 | C332: Jul | D332: 26 | E332: 2 | F332: 8527.53 | G332: tier - 2 | H332: tier - 2 | I332: R1013 | J332: =_xlfn.CONCAT(D332,"/",C332,"/",B332) -> 26/Jul/1977
A333: Id1291 | B333: 1979 | C333: Aug | D333: 13 | E333: 3 | F333: 8522 | G333: tier - 2 | H333: tier - 2 | I333: R1011 | J333: =_xlfn.CONCAT(D333,"/",C333,"/",B333) -> 13/Aug/1979
A334: Id1292 | B334: 1977 | C334: Dec | D334: 29 | E334: 2 | F334: 8520.03 | G334: tier - 2 | H334: tier - 3 | I334: R1011 | J334: =_xlfn.CONCAT(D334,"/",C334,"/",B334) -> 29/Dec/1977
A335: Id1293 | B335: 1977 | C335: Jun | D335: 21 | E335: 2 | F335: 8516.83 | G335: tier - 2 | H335: tier - 1 | I335: R1013 | J335: =_xlfn.CONCAT(D335,"/",C335,"/",B335) -> 21/Jun/1977
A336: Id1294 | B336: 1977 | C336: Dec | D336: 26 | E336: 2 | F336: 8515.76 | G336: tier - 2 | H336: tier - 2 | I336: R1013 | J336: =_xlfn.CONCAT(D336,"/",C336,"/",B336) -> 26/Dec/1977
A337: Id1295 | B337: 1993 | C337: Nov | D337: 10 | E337: 0 | F337: 8471.65 | G337: tier - 2 | H337: tier - 1 | I337: R1012 | J337: =_xlfn.CONCAT(D337,"/",C337,"/",B337) -> 10/Nov/1993
A338: Id1296 | B338: 1992 | C338: Sep | D338: 9 | E338: 0 | F338: 8466.35 | G338: tier - 2 | H338: tier - 2 | I338: R1012 | J338: =_xlfn.CONCAT(D338,"/",C338,"/",B338) -> 9/Sep/1992
A339: Id1297 | B339: 1972 | C339: Dec | D339: 26 | E339: 0 | F339: 8457.82 | G339: tier - 2 | H339: tier - 3 | I339: R1011 | J339: =_xlfn.CONCAT(D339,"/",C339,"/",B339) -> 26/Dec/1972
A340: Id1298 | B340: 1984 | C340: Jun | D340: 19 | E340: 3 | F340: 8450.82 | G340: tier - 2 | H340: tier - 2 | I340: R1025 | J340: =_xlfn.CONCAT(D340,"/",C340,"/",B340) -> 19/Jun/1984
A341: Id1299 | B341: 1966 | C341: Jun | D341: 12 | E341: 0 | F341: 8448.66 | G341: tier - 3 | H341: tier - 1 | I341: R1013 | J341: =_xlfn.CONCAT(D341,"/",C341,"/",B341) -> 12/Jun/1966
A342: Id13 | B342: 1962 | C342: Oct | D342: 11 | E342: 0 | F342: 48673.56 | G342: tier - 1 | H342: tier - 2 | I342: R1013 | J342: =_xlfn.CONCAT(D342,"/",C342,"/",B342) -> 11/Oct/1962
... A2344: Id999 | B2344: 1969 | C2344: Aug | D2344: 20 | E2344: 3 | F2344: 11253.42 | G2344: tier - 3 | H2344: tier - 1 | I2344: R1011 | J2344: =_xlfn.CONCAT(D2344,"/",C2344,"/",B2344) -> 20/Aug/1969

Sheet Data Cleaning 
A1: Customer ID | B1: year | C1: month | D1: date | E1: children | F1: charges | G1: Hospital tier | H1: City tier | I1: State ID | AB1: Customer ID | AC1: BMI | AD1: HBA1C | AE1: Heart Issues | AF1: Any Transplants | AG1: Cancer history | AH1: NumberOfMajorSurgeries | AI1: smoker | BD1: Customer ID | BE1: year | BF1: month | BG1: date | BH1: children | BI1: charges | BJ1: Hospital tier | BK1: City tier | BL1: State ID | CB1: smoker
A2: Id2335 | B2: 1992 | C2: Jul | D2: 9 | E2: 0 | F2: 563.84 | G2: tier - 2 | H2: tier - 3 | I2: R1013 | AB2: Id1 | AC2: 47.41 | AD2: 7.47 | AE2: No | AF2: No | AG2: No | AH2: No major surgery | AI2: yes | BD2: Id2335 | BE2: 1992 | BF2: Jul | BG2: 9 | BH2: 0 | BI2: 563.84 | BJ2: tier - 2 | BK2: tier - 3 | BL2: R1013 | CB2: yes
A3: Id2334 | B3: 1992 | C3: Nov | D3: 30 | E3: 0 | F3: 570.62 | G3: tier - 2 | H3: tier - 1 | I3: R1013 | AB3: Id2 | AC3: 30.36 | AD3: 5.77 | AE3: No | AF3: No | AG3: No | AH3: No major surgery | AI3: yes | BD3: Id2334 | BE3: 1992 | BF3: Nov | BG3: 30 | BH3: 0 | BI3: 570.62 | BJ3: tier - 2 | BK3: tier - 1 | BL3: R1013 | CB3: yes
A4: Id2333 | B4: 1993 | C4: Jun | D4: 30 | E4: 0 | F4: 600 | G4: tier - 2 | H4: tier - 1 | I4: R1013 | AB4: Id3 | AC4: 34.485 | AD4: 11.87 | AE4: yes | AF4: No | AG4: No | AH4: 2 | AI4: yes | BD4: Id2333 | BE4: 1993 | BF4: Jun | BG4: 30 | BH4: 0 | BI4: 600 | BJ4: tier - 2 | BK4: tier - 1 | BL4: R1013 | BN4: 2) Fill in the missing values of ‘month’ with Sep and ‘year’ with its average rounded to the nearest integer. | CB4: yes
A5: Id2332 | B5: 1992 | C5: Sep | D5: 13 | E5: 0 | F5: 604.54 | G5: tier - 3 | H5: tier - 3 | I5: R1013 | AB5: Id4 | AC5: 38.095 | AD5: 6.05 | AE5: No | AF5: No | AG5: No | AH5: No major surgery | AI5: yes | BD5: Id2332 | BE5: 1992 | BF5: Sep | BG5: 13 | BH5: 0 | BI5: 604.54 | BJ5: tier - 3 | BK5: tier - 3 | BL5: R1013 | CB5: yes
A6: Id2331 | B6: 1998 | C6: Jul | D6: 27 | E6: 0 | F6: 637.26 | G6: tier - 3 | H6: tier - 3 | I6: R1013 | L6: 1) Check for the number of missing values marked with '?' in each column of the “Medical Examinations” Table and "Hospitalization Details" Table. | AB6: Id5 | AC6: 35.53 | AD6: 5.45 | AE6: No | AF6: No | AG6: No | AH6: No major surgery | AI6: yes | AK6: 1) Check for the number of missing values marked with '?' in each column of the “Medical Examinations” Table and "Hospitalization Details" Table. | BD6: Id2331 | BE6: 1998 | BF6: Jul | BG6: 27 | BH6: 0 | BI6: 637.26 | BJ6: tier - 3 | BK6: tier - 3 | BL6: R1013 | CB6: yes
A7: Id2330 | B7: 2001 | C7: Nov | D7: 20 | E7: 0 | F7: 646.14 | G7: tier - 3 | H7: tier - 3 | I7: R1012 | AB7: Id6 | AC7: 32.8 | AD7: 6.59 | AE7: No | AF7: No | AG7: No | AH7: No major surgery | AI7: yes | BD7: Id2330 | BE7: 2001 | BF7: Nov | BG7: 20 | BH7: 0 | BI7: 646.14 | BJ7: tier - 3 | BK7: tier - 3 | BL7: R1012 | BN7: I REPLACED 3 MISSING VAUES | BR7: The average for missing values are 1975 &1979 | CB7: yes
A8: Id2329 | B8: 1993 | C8: Jun | D8: 1 | E8: 0 | F8: 650 | G8: tier - 3 | H8: tier - 3 | I8: R1013 | AB8: Id7 | AC8: 36.4 | AD8: 6.07 | AE8: No | AF8: No | AG8: No | AH8: No major surgery | AI8: yes | BD8: Id2329 | BE8: 1993 | BF8: Jun | BG8: 1 | BH8: 0 | BI8: 650 | BJ8: tier - 3 | BK8: tier - 3 | BL8: R1013 | CB8: yes
A9: Id2328 | B9: 1995 | C9: Jul | D9: 4 | E9: 0 | F9: 650 | G9: tier - 3 | H9: tier - 3 | I9: R1013 | AB9: Id8 | AC9: 36.96 | AD9: 7.93 | AE9: No | AF9: No | AG9: No | AH9: 3 | AI9: yes | BD9: Id2328 | BE9: 1995 | BF9: Jul | BG9: 4 | BH9: 0 | BI9: 650 | BJ9: tier - 3 | BK9: tier - 3 | BL9: R1013 | CB9: yes
A10: Id2327 | B10: 2002 | C10: Nov | D10: 29 | E10: 0 | F10: 668 | G10: tier - 3 | H10: tier - 2 | I10: R1012 | AB10: Id9 | AC10: 41.14 | AD10: 9.58 | AE10: yes | AF10: No | AG10: Yes | AH10: 1 | AI10: yes | BD10: Id2327 | BE10: 2002 | BF10: Nov | BG10: 29 | BH10: 0 | BI10: 668 | BJ10: tier - 3 | BK10: tier - 2 | BL10: R1012 | CB10: yes
A11: Id2326 | B11: 1997 | C11: Nov | D11: 9 | E11: 0 | F11: 670 | G11: tier - 3 | H11: tier - 3 | I11: R1013 | L11: =COUNTIF(A1:I2344,G13) -> 15 | AB11: Id10 | AC11: 38.06 | AD11: 10.79 | AE11: No | AF11: No | AG11: No | AH11: No major surgery | AI11: yes | AK11: =COUNTIF(AB1:AI2336,"?") -> 2 | AM11: TOTAL 2 VALUES FOUND ON MEDICAL EXAMINATION TABLE | BD11: Id2326 | BE11: 1997 | BF11: Nov | BG11: 9 | BH11: 0 | BI11: 670 | BJ11: tier - 3 | BK11: tier - 3 | BL11: R1013 | CB11: yes
A12: Id2325 | B12: 2001 | C12: Sep | D12: 12 | E12: 0 | F12: 687.54 | G12: tier - 3 | H12: tier - 2 | I12: R1013 | N12: TOTAL 15 VALUES FOUND ON HOSPITALISATION TABLE | AB12: Id11 | AC12: 37.7 | AD12: 5.96 | AE12: yes | AF12: No | AG12: No | AH12: 2 | AI12: yes | BD12: Id2325 | BE12: 2001 | BF12: Sep | BG12: 12 | BH12: 0 | BI12: 687.54 | BJ12: tier - 3 | BK12: tier - 2 | BL12: R1013 | CB12: yes
A13: Id2324 | B13: 1999 | C13: Dec | D13: 26 | E13: 0 | F13: 700 | G13: ? | H13: tier - 3 | I13: R1013 | AB13: Id12 | AC13: 42.13 | AD13: 11.9 | AE13: No | AF13: No | AG13: No | AH13: No major surgery | AI13: yes | BD13: Id2324 | BE13: 1999 | BF13: Dec | BG13: 26 | BH13: 0 | BI13: 700 | BJ13: TIER 2 | BK13: tier - 3 | BL13: R1013 | BN13: 3)Determine the most frequently occurring values in the ‘smoker’, 'Hospital tier' and 'City tier' columns, and fill in the missing values accordingly. | CB13: yes
A14: Id2323 | B14: 1999 | C14: Dec | D14: 14 | E14: 0 | F14: 722.99 | G14: tier - 3 | H14: tier - 1 | I14: R1013 | AB14: Id13 | AC14: 40.92 | AD14: 8.41 | AE14: No | AF14: No | AG14: No | AH14: No major surgery | AI14: yes | BD14: Id2323 | BE14: 1999 | BF14: Dec | BG14: 14 | BH14: 0 | BI14: 722.99 | BJ14: tier - 3 | BK14: tier - 1 | BL14: R1013 | CB14: yes
A15: Id2322 | B15: 2002 | C15: ? | D15: 19 | E15: 0 | F15: 750 | G15: tier - 3 | H15: tier - 1 | I15: R1012 | AB15: Id14 | AC15: 40.565 | AD15: 7.02 | AE15: No | AF15: No | AG15: No | AH15: No major surgery | AI15: yes | BD15: Id2322 | BE15: 2002 | BF15: SEP | BG15: 19 | BH15: 0 | BI15: 750 | BJ15: tier - 3 | BK15: tier - 1 | BL15: R1012 | CB15: yes
A16: Id2321 | B16: 1993 | C16: Aug | D16: 9 | E16: 0 | F16: 760 | G16: tier - 3 | H16: tier - 1 | I16: R1013 | AB16: Id15 | AC16: 36.385 | AD16: 7.59 | AE16: yes | AF16: No | AG16: No | AH16: 2 | AI16: yes | BD16: Id2321 | BE16: 1993 | BF16: Aug | BG16: 9 | BH16: 0 | BI16: 760 | BJ16: tier - 3 | BK16: tier - 1 | BL16: R1013 | CB16: yes
A17: Id2320 | B17: 1996 | C17: Oct | D17: 22 | E17: 0 | F17: 760 | G17: tier - 3 | H17: tier - 3 | I17: R1013 | M17: IN BOTH TABLES I FOUND 17 VALUES WITH "?" | AB17: Id16 | AC17: 39.9 | AD17: 11.32 | AE17: No | AF17: No | AG17: No | AH17: No major surgery | AI17: yes | BD17: Id2320 | BE17: 1996 | BF17: Oct | BG17: 22 | BH17: 0 | BI17: 760 | BJ17: tier - 3 | BK17: tier - 3 | BL17: R1013 | BM17: HOSPITAL TIER | BS17: City tier | BX17: SMOKER | CB17: yes
A18: Id2319 | B18: 1993 | C18: Jun | D18: 28 | E18: 0 | F18: 770 | G18: tier - 3 | H18: tier - 3 | I18: R1013 | AB18: Id17 | AC18: 33.8 | AD18: 7.67 | AE18: No | AF18: No | AG18: No | AH18: 3 | AI18: yes | BD18: Id2319 | BE18: 1993 | BF18: Jun | BG18: 28 | BH18: 0 | BI18: 770 | BJ18: tier - 3 | BK18: tier - 3 | BL18: R1013 | BN18: TIER 1 | BO18: =COUNTIF($BJ$2:$BJ$2344,BJ2344) -> 309 | BS18: TIER 1 | BT18: =COUNTIF($BK$2:$BK$2344,BK14) -> 734 | BX18: YES | BY18: =COUNTIF(CB2:CB2336,CB6) -> 488 | CB18: yes
A19: Id2318 | B19: 1996 | C19: ? | D19: 18 | E19: 0 | F19: 770.38 | G19: tier - 3 | H19: ? | I19: R1012 | AB19: Id18 | AC19: 36.765 | AD19: 7.29 | AE19: yes | AF19: No | AG19: Yes | AH19: 1 | AI19: yes | BD19: Id2318 | BE19: 1996 | BF19: SEP | BG19: 18 | BH19: 0 | BI19: 770.38 | BJ19: tier - 3 | BK19: TIER 2 | BL19: R1012 | BN19: TIER 2 | BO19: =COUNTIF($BJ$2:$BJ$2344,BJ2) -> 1339 | BS19: TIER 2 | BT19: =COUNTIF($BK$2:$BK$2344,BK10) -> 812 | BX19: NO | BY19: =COUNTIF(CB2:CB2336,CB2325) -> 1847 | CB19: yes
A20: Id2317 | B20: 1995 | C20: Dec | D20: 7 | E20: 0 | F20: 773.54 | G20: tier - 3 | H20: tier - 2 | I20: R1013 | AB20: Id19 | AC20: 36.955 | AD20: 4.72 | AE20: yes | AF20: No | AG20: No | AH20: 1 | AI20: yes | BD20: Id2317 | BE20: 1995 | BF20: Dec | BG20: 7 | BH20: 0 | BI20: 773.54 | BJ20: tier - 3 | BK20: tier - 2 | BL20: R1013 | BN20: TIER 3 | BO20: =COUNTIF($BJ$2:$BJ$2344,BJ12) -> 694 | BS20: TIER 3 | BT20: =COUNTIF($BK$2:$BK$2344,BK13) -> 796 | CB20: yes
A21: Id2316 | B21: 2004 | C21: Oct | D21: 7 | E21: 0 | F21: 830.52 | G21: tier - 3 | H21: tier - 2 | I21: R1011 | AB21: Id20 | AC21: 42.9 | AD21: 11.41 | AE21: No | AF21: No | AG21: No | AH21: No major surgery | AI21: yes | BD21: Id2316 | BE21: 2004 | BF21: Oct | BG21: 7 | BH21: 0 | BI21: 830.52 | BJ21: tier - 3 | BK21: tier - 2 | BL21: R1011 | CB21: yes
A22: Id2315 | B22: 2000 | C22: Nov | D22: 18 | E22: 0 | F22: 865.41 | G22: tier - 3 | H22: tier - 1 | I22: R1013 | AB22: Id21 | AC22: 36.3 | AD22: 11.5 | AE22: yes | AF22: No | AG22: No | AH22: 2 | AI22: yes | BD22: Id2315 | BE22: 2000 | BF22: Nov | BG22: 18 | BH22: 0 | BI22: 865.41 | BJ22: tier - 3 | BK22: tier - 1 | BL22: R1013 | BN22: HERE TIER 2 IS MOST REPEATED VALUE | BS22: HERE ALSO TIER 2 IS MOST REPEATED VALUE | BX22: HERE NO IS THE MOST REPEATED VALUE | CB22: yes
A23: Id2314 | B23: 1993 | C23: Nov | D23: 27 | E23: 0 | F23: 896.21 | G23: tier - 3 | H23: tier - 1 | I23: R1013 | AB23: Id22 | AC23: 32.2 | AD23: 6.22 | AE23: yes | AF23: No | AG23: No | AH23: 2 | AI23: yes | BD23: Id2314 | BE23: 1993 | BF23: Nov | BG23: 27 | BH23: 0 | BI23: 896.21 | BJ23: tier - 3 | BK23: tier - 1 | BL23: R1013 | CB23: yes
A24: Id2313 | B24: 1994 | C24: Oct | D24: 30 | E24: 0 | F24: 915.07 | G24: tier - 3 | H24: tier - 1 | I24: R1013 | AB24: Id23 | AC24: 31.3 | AD24: 11.38 | AE24: No | AF24: No | AG24: No | AH24: 3 | AI24: yes | BD24: Id2313 | BE24: 1994 | BF24: Oct | BG24: 30 | BH24: 0 | BI24: 915.07 | BJ24: tier - 3 | BK24: tier - 1 | BL24: R1013 | CB24: yes
A25: Id2312 | B25: 1995 | C25: Oct | D25: 28 | E25: 0 | F25: 928.59 | G25: tier - 3 | H25: tier - 1 | I25: R1013 | AB25: Id24 | AC25: 41.8 | AD25: 7.89 | AE25: yes | AF25: No | AG25: No | AH25: 2 | AI25: yes | BD25: Id2312 | BE25: 1995 | BF25: Oct | BG25: 28 | BH25: 0 | BI25: 928.59 | BJ25: tier - 3 | BK25: tier - 1 | BL25: R1013 | BN25: 4) If any 'State ID' values are missing, consider filling them with 'Unknown' or using another appropriate strategy. | CB25: yes
A26: Id2311 | B26: 2001 | C26: Aug | D26: 19 | E26: 0 | F26: 964.71 | G26: tier - 3 | H26: tier - 2 | I26: R1013 | AB26: Id25 | AC26: 35.09 | AD26: 4.38 | AE26: yes | AF26: No | AG26: No | AH26: 2 | AI26: yes | BD26: Id2311 | BE26: 2001 | BF26: Aug | BG26: 19 | BH26: 0 | BI26: 964.71 | BJ26: tier - 3 | BK26: tier - 2 | BL26: R1013 | CB26: yes
A27: Id2310 | B27: 1994 | C27: Nov | D27: 22 | E27: 0 | F27: 1006.65 | G27: tier - 3 | H27: tier - 2 | I27: R1013 | AB27: Id26 | AC27: 33.88 | AD27: 7.01 | AE27: No | AF27: No | AG27: No | AH27: 3 | AI27: yes | BD27: Id2310 | BE27: 1994 | BF27: Nov | BG27: 22 | BH27: 0 | BI27: 1006.65 | BJ27: tier - 3 | BK27: tier - 2 | BL27: R1013 | CB27: yes
A28: Id2309 | B28: 2000 | C28: Oct | D28: 9 | E28: 0 | F28: 1012 | G28: tier - 3 | H28: tier - 2 | I28: R1013 | AB28: Id27 | AC28: 30.875 | AD28: 11.88 | AE28: No | AF28: No | AG28: No | AH28: No major surgery | AI28: yes | BD28: Id2309 | BE28: 2000 | BF28: Oct | BG28: 9 | BH28: 0 | BI28: 1012 | BJ28: tier - 3 | BK28: tier - 2 | BL28: R1013 | BN28: I Found 2 missing values and I replaced with "UNKNOWN" successfully | CB28: yes
A29: Id2308 | B29: 1999 | C29: Aug | D29: 5 | E29: 0 | F29: 1019 | G29: tier - 3 | H29: tier - 2 | I29: R1013 | AB29: Id28 | AC29: 36.86 | AD29: 5.19 | AE29: yes | AF29: No | AG29: Yes | AH29: 1 | AI29: yes | BD29: Id2308 | BE29: 1999 | BF29: Aug | BG29: 5 | BH29: 0 | BI29: 1019 | BJ29: tier - 3 | BK29: tier - 2 | BL29: R1013 | CB29: yes
A30: Id2307 | B30: 1995 | C30: Oct | D30: 5 | E30: 0 | F30: 1033.74 | G30: tier - 3 | H30: tier - 1 | I30: R1013 | AB30: Id29 | AC30: 35.86 | AD30: 6.74 | AE30: yes | AF30: No | AG30: No | AH30: 2 | AI30: yes | BD30: Id2307 | BE30: 1995 | BF30: Oct | BG30: 5 | BH30: 0 | BI30: 1033.74 | BJ30: tier - 3 | BK30: tier - 1 | BL30: R1013 | CB30: yes
A31: Id2306 | B31: 1994 | C31: Nov | D31: 17 | E31: 0 | F31: 1044 | G31: tier - 3 | H31: tier - 2 | I31: R1013 | AB31: Id30 | AC31: 37.05 | AD31: 8.44 | AE31: No | AF31: No | AG31: No | AH31: No major surgery | AI31: yes | BD31: Id2306 | BE31: 1994 | BF31: Nov | BG31: 17 | BH31: 0 | BI31: 1044 | BJ31: tier - 3 | BK31: tier - 2 | BL31: R1013 | CB31: yes
A32: Id2305 | B32: 2002 | C32: Jul | D32: 20 | E32: 0 | F32: 1047 | G32: tier - 3 | H32: tier - 1 | I32: R1013 | AB32: Id31 | AC32: 43.89 | AD32: 8.71 | AE32: No | AF32: No | AG32: No | AH32: No major surgery | AI32: yes | BD32: Id2305 | BE32: 2002 | BF32: Jul | BG32: 20 | BH32: 0 | BI32: 1047 | BJ32: tier - 3 | BK32: tier - 1 | BL32: R1013 | CB32: yes
A33: Id2304 | B33: 2002 | C33: Jul | D33: 1 | E33: 0 | F33: 1049 | G33: tier - 3 | H33: tier - 2 | I33: R1012 | AB33: Id32 | AC33: 42.35 | AD33: 5.08 | AE33: yes | AF33: No | AG33: No | AH33: No major surgery | AI33: yes | BD33: Id2304 | BE33: 2002 | BF33: Jul | BG33: 1 | BH33: 0 | BI33: 1049 | BJ33: tier - 3 | BK33: tier - 2 | BL33: R1012 | CB33: yes
A34: Id2303 | B34: 1995 | C34: Jun | D34: 1 | E34: 0 | F34: 1056 | G34: tier - 3 | H34: tier - 2 | I34: R1013 | AB34: Id33 | AC34: 31.35 | AD34: 6.86 | AE34: No | AF34: No | AG34: No | AH34: No major surgery | AI34: yes | BD34: Id2303 | BE34: 1995 | BF34: Jun | BG34: 1 | BH34: 0 | BI34: 1056 | BJ34: tier - 3 | BK34: tier - 2 | BL34: R1013 | CB34: yes
A35: Id2302 | B35: 1993 | C35: Sep | D35: 28 | E35: 0 | F35: 1068 | G35: tier - 3 | H35: tier - 1 | I35: R1013 | AB35: Id34 | AC35: 47.6 | AD35: 5.95 | AE35: yes | AF35: No | AG35: No | AH35: No major surgery | AI35: yes | BD35: Id2302 | BE35: 1993 | BF35: Sep | BG35: 28 | BH35: 0 | BI35: 1068 | BJ35: tier - 3 | BK35: tier - 1 | BL35: R1013 | CB35: yes
A36: Id2301 | B36: 2004 | C36: Aug | D36: 24 | E36: 0 | F36: 1070 | G36: tier - 3 | H36: tier - 3 | I36: R1013 | AB36: Id35 | AC36: 46.2 | AD36: 6.09 | AE36: No | AF36: No | AG36: Yes | AH36: 1 | AI36: yes | BD36: Id2301 | BE36: 2004 | BF36: Aug | BG36: 24 | BH36: 0 | BI36: 1070 | BJ36: tier - 3 | BK36: tier - 3 | BL36: R1013 | CB36: yes
A37: Id2300 | B37: 1997 | C37: Aug | D37: 13 | E37: 0 | F37: 1071 | G37: tier - 3 | H37: tier - 3 | I37: R1013 | AB37: Id36 | AC37: 32.015 | AD37: 11.75 | AE37: No | AF37: No | AG37: No | AH37: No major surgery | AI37: yes | BD37: Id2300 | BE37: 1997 | BF37: Aug | BG37: 13 | BH37: 0 | BI37: 1071 | BJ37: tier - 3 | BK37: tier - 3 | BL37: R1013 | CB37: yes
A38: Id2299 | B38: 1998 | C38: Dec | D38: 26 | E38: 0 | F38: 1082 | G38: tier - 3 | H38: tier - 2 | I38: R1013 | AB38: Id37 | AC38: 40.565 | AD38: 7.37 | AE38: No | AF38: No | AG38: No | AH38: No major surgery | AI38: yes | BD38: Id2299 | BE38: 1998 | BF38: Dec | BG38: 26 | BH38: 0 | BI38: 1082 | BJ38: tier - 3 | BK38: tier - 2 | BL38: R1013 | CB38: yes
A39: Id2298 | B39: 2002 | C39: Aug | D39: 13 | E39: 0 | F39: 1086 | G39: tier - 3 | H39: tier - 3 | I39: R1013 | AB39: Id38 | AC39: 32.45 | AD39: 11.91 | AE39: No | AF39: No | AG39: No | AH39: No major surgery | AI39: yes | BD39: Id2298 | BE39: 2002 | BF39: Aug | BG39: 13 | BH39: 0 | BI39: 1086 | BJ39: tier - 3 | BK39: tier - 3 | BL39: R1013 | CB39: yes
A40: Id2297 | B40: 2004 | C40: Nov | D40: 12 | E40: 0 | F40: 1121.87 | G40: tier - 3 | H40: tier - 1 | I40: R1013 | AB40: Id39 | AC40: 34.96 | AD40: 6.52 | AE40: No | AF40: No | AG40: No | AH40: No major surgery | AI40: yes | BD40: Id2297 | BE40: 2004 | BF40: Nov | BG40: 12 | BH40: 0 | BI40: 1121.87 | BJ40: tier - 3 | BK40: tier - 1 | BL40: R1013 | CB40: yes
...

Sheet Data Transformation
A1: Customer ID | B1: TITLE | C1: FIRST NAME | D1: LAST NAME | T1: Customer ID | U1: BMI | V1: HBA1C | W1: Heart Issues | X1: Any Transplants | Y1: Cancer history | Z1: NumberOfMajorSurgeries | AA1: smoker | AV1: Customer ID | AW1: BMI | AX1: HBA1C | AY1: Heart Issues | AZ1: Any Transplants | BA1: Cancer history | BB1: NumberOfMajorSurgeries | BC1: smoker | BR1: BMI | BS1: Weight Status | BV1: HBA1C | BW1: Diabetes Status | CJ1: Customer ID | CK1: year | CL1: month | CM1: date | CN1: children | CO1: charges | CP1: Hospital tier | CQ1: City tier | CR1: State ID | CW1: Date of Birth | CZ1: Customer ID | DA1: year | DB1: month | DC1: date | DD1: children | DE1: charges | DF1: Hospital tier | DG1: City tier | DH1: State ID | DZ1: Customer ID | EA1: AGE
A2: Id1 | B2: Ms. | C2: Hawks | D2: Kelly | T2: Id1 | U2: 47.41 | V2: 7.47 | W2: No | X2: No | Y2: No | Z2: 0 | AA2: yes | AV2: Id1 | AW2: 47.41 | AX2: 7.47 | AY2: No | AZ2: No | BA2: No | BB2: No major surgery | BC2: yes | BE2: 3) Check for inconsistencies in the 'Heart Issues' and 'smoker' columns and propose corrective actions if necessary. | BR2: 47.41 | BS2: {=_xlfn.IFS(BR2<18.5,"UNDER WEIGHT",BR2<=24.9,"NORMAL WEIGHT",BR2<=29.9,"OVER WEIGHT",BR2>=30,"OBESITY")} -> OBESITY | BV2: 7.47 | BW2: {=_xlfn.IFS(BV2<=5.7,"NORMAL",BV2<=6.4,"Prediabetes",BV2>=6.5,"Diabetes")} -> Diabetes | CJ2: Id2335 | CK2: 1992 | CL2: Jul | CM2: 9 | CN2: 0 | CO2: 563.84 | CP2: tier - 2 | CQ2: tier - 3 | CR2: R1013 | CS2: 6) Merge ‘year’, ‘month’ and ‘date’ columns in the “Hospitalization Details” Table into one column named ‘Date of Birth’ and format it in ‘DD-MMM-YYYY’ custom format. | CW2: =_xlfn.CONCAT(CM2,"/",CL2,"/",CK2) -> 9/Jul/1992 | CZ2: Id2335 | DA2: 1992 | DB2: Jul | DC2: 9 | DD2: 0 | DE2: 563.84 | DF2: tier - 2 | DG2: tier - 3 | DH2: R1013 | DJ2: 8) Format ‘charges’ column as currency ($). | DZ2: Id2335 | EA2: =YEAR(DATE(2023,6,8))-YEAR(CW2) -> 31
A3: Id2 | B3: Mr. | C3: Lehner | D3: Matthew D | F3: 1) Split the ‘names’ column in the “Customer Names” Table into 3 meaningful columns: ‘Title’, ‘First Name’, and ‘Last Name’. | T3: Id2 | U3: 30.36 | V3: 5.77 | W3: No | X3: No | Y3: No | Z3: 0 | AA3: yes | AC3: 2) Convert the "NumberOfMajorSurgeries" column in the “Medical Examinations” Table to numerical data by replacing non-numeric characters with meaningful numerical values. | AV3: Id2 | AW3: 30.36 | AX3: 5.77 | AY3: No | AZ3: No | BA3: No | BB3: No major surgery | BC3: yes | BR3: 30.36 | BS3: {=_xlfn.IFS(BR3<18.5,"UNDER WEIGHT",BR3<=24.9,"NORMAL WEIGHT",BR3<=29.9,"OVER WEIGHT",BR3>=30,"OBESITY")} -> OBESITY | BV3: 5.77 | BW3: {=_xlfn.IFS(BV3<=5.7,"NORMAL",BV3<=6.4,"Prediabetes",BV3>=6.5,"Diabetes")} -> Prediabetes | BY3: 5) Create a new column named “Diabetes Status” and fill it as per the information given below: | CJ3: Id2334 | CK3: 1992 | CL3: Nov | CM3: 30 | CN3: 0 | CO3: 570.62 | CP3: tier - 2 | CQ3: tier - 1 | CR3: R1013 | CW3: =_xlfn.CONCAT(CM3,"/",CL3,"/",CK3) -> 30/Nov/1992 | CZ3: Id2334 | DA3: 1992 | DB3: Nov | DC3: 30 | DD3: 0 | DE3: 570.62 | DF3: tier - 2 | DG3: tier - 1 | DH3: R1013 | DN3: 7) Calculate the ‘Age’ of each customer based on their ‘Date of Birth’ and the date of collection of the dataset, which is 8thJune 2023. | DZ3: Id2334 | EA3: =YEAR(DATE(2023,6,8))-YEAR(CW3) -> 31
A4: Id3 | B4: Mr. | C4: Lu | D4: Phil | T4: Id3 | U4: 34.485 | V4: 11.87 | W4: yes | X4: No | Y4: No | Z4: 2 | AA4: yes | AV4: Id3 | AW4: 34.485 | AX4: 11.87 | AY4: yes | AZ4: No | BA4: No | BB4: 2 | BC4: yes | BR4: 34.485 | BS4: {=_xlfn.IFS(BR4<18.5,"UNDER WEIGHT",BR4<=24.9,"NORMAL WEIGHT",BR4<=29.9,"OVER WEIGHT",BR4>=30,"OBESITY")} -> OBESITY | BV4: 11.87 | BW4: {=_xlfn.IFS(BV4<=5.7,"NORMAL",BV4<=6.4,"Prediabetes",BV4>=6.5,"Diabetes")} -> Diabetes | CJ4: Id2333 | CK4: 1993 | CL4: Jun | CM4: 30 | CN4: 0 | CO4: 600 | CP4: tier - 2 | CQ4: tier - 1 | CR4: R1013 | CW4: =_xlfn.CONCAT(CM4,"/",CL4,"/",CK4) -> 30/Jun/1993 | CZ4: Id2333 | DA4: 1993 | DB4: Jun | DC4: 30 | DD4: 0 | DE4: 600 | DF4: tier - 2 | DG4: tier - 1 | DH4: R1013 | DZ4: Id2333 | EA4: =YEAR(DATE(2023,6,8))-YEAR(CW4) -> 30
A5: Id4 | B5: Ms. | C5: Osborne | D5: Kelsey | T5: Id4 | U5: 38.095 | V5: 6.05 | W5: No | X5: No | Y5: No | Z5: 0 | AA5: yes | AV5: Id4 | AW5: 38.095 | AX5: 6.05 | AY5: No | AZ5: No | BA5: No | BB5: No major surgery | BC5: yes | BE5: Here I don’t Found any inconsistencies in "Heart issues" column But I Found 2 inconsistencies in smoker column and i replace with that most repeated value | BR5: 38.095 | BS5: {=_xlfn.IFS(BR5<18.5,"UNDER WEIGHT",BR5<=24.9,"NORMAL WEIGHT",BR5<=29.9,"OVER WEIGHT",BR5>=30,"OBESITY")} -> OBESITY | BV5: 6.05 | BW5: {=_xlfn.IFS(BV5<=5.7,"NORMAL",BV5<=6.4,"Prediabetes",BV5>=6.5,"Diabetes")} -> Prediabetes | CJ5: Id2332 | CK5: 1992 | CL5: Sep | CM5: 13 | CN5: 0 | CO5: 604.54 | CP5: tier - 3 | CQ5: tier - 3 | CR5: R1013 | CW5: =_xlfn.CONCAT(CM5,"/",CL5,"/",CK5) -> 13/Sep/1992 | CZ5: Id2332 | DA5: 1992 | DB5: Sep | DC5: 13 | DD5: 0 | DE5: 604.54 | DF5: tier - 3 | DG5: tier - 3 | DH5: R1013 | DZ5: Id2332 | EA5: =YEAR(DATE(2023,6,8))-YEAR(CW5) -> 31
A6: Id5 | B6: Ms. | C6: Kadala | D6: Kristyn | F6: I splited the columns | T6: Id5 | U6: 35.53 | V6: 5.45 | W6: No | X6: No | Y6: No | Z6: 0 | AA6: yes | AV6: Id5 | AW6: 35.53 | AX6: 5.45 | AY6: No | AZ6: No | BA6: No | BB6: No major surgery | BC6: yes | BR6: 35.53 | BS6: {=_xlfn.IFS(BR6<18.5,"UNDER WEIGHT",BR6<=24.9,"NORMAL WEIGHT",BR6<=29.9,"OVER WEIGHT",BR6>=30,"OBESITY")} -> OBESITY | BV6: 5.45 | BW6: {=_xlfn.IFS(BV6<=5.7,"NORMAL",BV6<=6.4,"Prediabetes",BV6>=6.5,"Diabetes")} -> NORMAL | CJ6: Id2331 | CK6: 1998 | CL6: Jul | CM6: 27 | CN6: 0 | CO6: 637.26 | CP6: tier - 3 | CQ6: tier - 3 | CR6: R1013 | CW6: =_xlfn.CONCAT(CM6,"/",CL6,"/",CK6) -> 27/Jul/1998 | CZ6: Id2331 | DA6: 1998 | DB6: Jul | DC6: 27 | DD6: 0 | DE6: 637.26 | DF6: tier - 3 | DG6: tier - 3 | DH6: R1013 | DZ6: Id2331 | EA6: =YEAR(DATE(2023,6,8))-YEAR(CW6) -> 25
A7: Id6 | B7: Mr. | C7: Baker | D7: Russell B. | T7: Id6 | U7: 32.8 | V7: 6.59 | W7: No | X7: No | Y7: No | Z7: 0 | AA7: yes | AE7: here I converted "No Major Surgery " to "0" | AV7: Id6 | AW7: 32.8 | AX7: 6.59 | AY7: No | AZ7: No | BA7: No | BB7: No major surgery | BC7: yes | BR7: 32.8 | BS7: {=_xlfn.IFS(BR7<18.5,"UNDER WEIGHT",BR7<=24.9,"NORMAL WEIGHT",BR7<=29.9,"OVER WEIGHT",BR7>=30,"OBESITY")} -> OBESITY | BV7: 6.59 | BW7: {=_xlfn.IFS(BV7<=5.7,"NORMAL",BV7<=6.4,"Prediabetes",BV7>=6.5,"Diabetes")} -> Diabetes | BY7: Here I created a Table "Diabetes Status" | CJ7: Id2330 | CK7: 2001 | CL7: Nov | CM7: 20 | CN7: 0 | CO7: 646.14 | CP7: tier - 3 | CQ7: tier - 3 | CR7: R1012 | CW7: =_xlfn.CONCAT(CM7,"/",CL7,"/",CK7) -> 20/Nov/2001 | CZ7: Id2330 | DA7: 2001 | DB7: Nov | DC7: 20 | DD7: 0 | DE7: 646.14 | DF7: tier - 3 | DG7: tier - 3 | DH7: R1012 | DZ7: Id2330 | EA7: =YEAR(DATE(2023,6,8))-YEAR(CW7) -> 22
A8: Id7 | B8: Mr. | C8: Macpherson | D8: Scott | T8: Id7 | U8: 36.4 | V8: 6.07 | W8: No | X8: No | Y8: No | Z8: 0 | AA8: yes | AV8: Id7 | AW8: 36.4 | AX8: 6.07 | AY8: No | AZ8: No | BA8: No | BB8: No major surgery | BC8: yes | BR8: 36.4 | BS8: {=_xlfn.IFS(BR8<18.5,"UNDER WEIGHT",BR8<=24.9,"NORMAL WEIGHT",BR8<=29.9,"OVER WEIGHT",BR8>=30,"OBESITY")} -> OBESITY | BV8: 6.07 | BW8: {=_xlfn.IFS(BV8<=5.7,"NORMAL",BV8<=6.4,"Prediabetes",BV8>=6.5,"Diabetes")} -> Prediabetes | CJ8: Id2329 | CK8: 1993 | CL8: Jun | CM8: 1 | CN8: 0 | CO8: 650 | CP8: tier - 3 | CQ8: tier - 3 | CR8: R1013 | CW8: =_xlfn.CONCAT(CM8,"/",CL8,"/",CK8) -> 1/Jun/1993 | CZ8: Id2329 | DA8: 1993 | DB8: Jun | DC8: 1 | DD8: 0 | DE8: 650 | DF8: tier - 3 | DG8: tier - 3 | DH8: R1013 | DO8: HERE I CALCULATED THE AGE BASED ON THEIR DATE OF BIRTH | DZ8: Id2329 | EA8: =YEAR(DATE(2023,6,8))-YEAR(CW8) -> 30
A9: Id8 | B9: Mr. | C9: Hallman | D9: Stephen | T9: Id8 | U9: 36.96 | V9: 7.93 | W9: No | X9: No | Y9: No | Z9: 3 | AA9: yes | AV9: Id8 | AW9: 36.96 | AX9: 7.93 | AY9: No | AZ9: No | BA9: No | BB9: 3 | BC9: yes | BR9: 36.96 | BS9: {=_xlfn.IFS(BR9<18.5,"UNDER WEIGHT",BR9<=24.9,"NORMAL WEIGHT",BR9<=29.9,"OVER WEIGHT",BR9>=30,"OBESITY")} -> OBESITY | BV9: 7.93 | BW9: {=_xlfn.IFS(BV9<=5.7,"NORMAL",BV9<=6.4,"Prediabetes",BV9>=6.5,"Diabetes")} -> Diabetes | CJ9: Id2328 | CK9: 1995 | CL9: Jul | CM9: 4 | CN9: 0 | CO9: 650 | CP9: tier - 3 | CQ9: tier - 3 | CR9: R1013 | CW9: =_xlfn.CONCAT(CM9,"/",CL9,"/",CK9) -> 4/Jul/1995 | CZ9: Id2328 | DA9: 1995 | DB9: Jul | DC9: 4 | DD9: 0 | DE9: 650 | DF9: tier - 3 | DG9: tier - 3 | DH9: R1013 | DZ9: Id2328 | EA9: =YEAR(DATE(2023,6,8))-YEAR(CW9) -> 28
A10: Id9 | B10: Mr. | C10: Moran | D10: Patrick R. | T10: Id9 | U10: 41.14 | V10: 9.58 | W10: yes | X10: No | Y10: Yes | Z10: 1 | AA10: yes | AV10: Id9 | AW10: 41.14 | AX10: 9.58 | AY10: yes | AZ10: No | BA10: Yes | BB10: 1 | BC10: yes | BE10: 4) Create a new column named “Weight Status” that categorizes BMI into different categories as below: | BR10: 41.14 | BS10: {=_xlfn.IFS(BR10<18.5,"UNDER WEIGHT",BR10<=24.9,"NORMAL WEIGHT",BR10<=29.9,"OVER WEIGHT",BR10>=30,"OBESITY")} -> OBESITY | BV10: 9.58 | BW10: {=_xlfn.IFS(BV10<=5.7,"NORMAL",BV10<=6.4,"Prediabetes",BV10>=6.5,"Diabetes")} -> Diabetes | CJ10: Id2327 | CK10: 2002 | CL10: Nov | CM10: 29 | CN10: 0 | CO10: 668 | CP10: tier - 3 | CQ10: tier - 2 | CR10: R1012 | CW10: =_xlfn.CONCAT(CM10,"/",CL10,"/",CK10) -> 29/Nov/2002 | CZ10: Id2327 | DA10: 2002 | DB10: Nov | DC10: 29 | DD10: 0 | DE10: 668 | DF10: tier - 3 | DG10: tier - 2 | DH10: R1012 | DZ10: Id2327 | EA10: =YEAR(DATE(2023,6,8))-YEAR(CW10) -> 21
A11: Id10 | B11: Ms. | C11: Benner | D11: Brooke N. | T11: Id10 | U11: 38.06 | V11: 10.79 | W11: No | X11: No | Y11: No | Z11: 0 | AA11: yes | AV11: Id10 | AW11: 38.06 | AX11: 10.79 | AY11: No | AZ11: No | BA11: No | BB11: No major surgery | BC11: yes | BR11: 38.06 | BS11: {=_xlfn.IFS(BR11<18.5,"UNDER WEIGHT",BR11<=24.9,"NORMAL WEIGHT",BR11<=29.9,"OVER WEIGHT",BR11>=30,"OBESITY")} -> OBESITY | BV11: 10.79 | BW11: {=_xlfn.IFS(BV11<=5.7,"NORMAL",BV11<=6.4,"Prediabetes",BV11>=6.5,"Diabetes")} -> Diabetes | CJ11: Id2326 | CK11: 1997 | CL11: Nov | CM11: 9 | CN11: 0 | CO11: 670 | CP11: tier - 3 | CQ11: tier - 3 | CR11: R1013 | CW11: =_xlfn.CONCAT(CM11,"/",CL11,"/",CK11) -> 9/Nov/1997 | CZ11: Id2326 | DA11: 1997 | DB11: Nov | DC11: 9 | DD11: 0 | DE11: 670 | DF11: tier - 3 | DG11: tier - 3 | DH11: R1013 | DZ11: Id2326 | EA11: =YEAR(DATE(2023,6,8))-YEAR(CW11) -> 26
A12: Id11 | B12: Ms. | C12: Fierro Vargas | D12: Paola Andrea | T12: Id11 | U12: 37.7 | V12: 5.96 | W12: yes | X12: No | Y12: No | Z12: 2 | AA12: yes | AV12: Id11 | AW12: 37.7 | AX12: 5.96 | AY12: yes | AZ12: No | BA12: No | BB12: 2 | BC12: yes | BR12: 37.7 | BS12: {=_xlfn.IFS(BR12<18.5,"UNDER WEIGHT",BR12<=24.9,"NORMAL WEIGHT",BR12<=29.9,"OVER WEIGHT",BR12>=30,"OBESITY")} -> OBESITY | BV12: 5.96 | BW12: {=_xlfn.IFS(BV12<=5.7,"NORMAL",BV12<=6.4,"Prediabetes",BV12>=6.5,"Diabetes")} -> Prediabetes | CJ12: Id2325 | CK12: 2001 | CL12: Sep | CM12: 12 | CN12: 0 | CO12: 687.54 | CP12: tier - 3 | CQ12: tier - 2 | CR12: R1013 | CW12: =_xlfn.CONCAT(CM12,"/",CL12,"/",CK12) -> 12/Sep/2001 | CZ12: Id2325 | DA12: 2001 | DB12: Sep | DC12: 12 | DD12: 0 | DE12: 687.54 | DF12: tier - 3 | DG12: tier - 2 | DH12: R1013 | DZ12: Id2325 | EA12: =YEAR(DATE(2023,6,8))-YEAR(CW12) -> 22
A13: Id12 | B13: Mr. | C13: Franz | D13: David | T13: Id12 | U13: 42.13 | V13: 11.9 | W13: No | X13: No | Y13: No | Z13: 0 | AA13: yes | AV13: Id12 | AW13: 42.13 | AX13: 11.9 | AY13: No | AZ13: No | BA13: No | BB13: No major surgery | BC13: yes | BE13: Here I created new Column "Weight Status" using ifs function | BR13: 42.13 | BS13: {=_xlfn.IFS(BR13<18.5,"UNDER WEIGHT",BR13<=24.9,"NORMAL WEIGHT",BR13<=29.9,"OVER WEIGHT",BR13>=30,"OBESITY")} -> OBESITY | BV13: 11.9 | BW13: {=_xlfn.IFS(BV13<=5.7,"NORMAL",BV13<=6.4,"Prediabetes",BV13>=6.5,"Diabetes")} -> Diabetes | CJ13: Id2324 | CK13: 1999 | CL13: Dec | CM13: 26 | CN13: 0 | CO13: 700 | CP13: tier - 2 | CQ13: tier - 3 | CR13: R1013 | CW13: =_xlfn.CONCAT(CM13,"/",CL13,"/",CK13) -> 26/Dec/1999 | CZ13: Id2324 | DA13: 1999 | DB13: Dec | DC13: 26 | DD13: 0 | DE13: 700 | DF13: tier - 2 | DG13: tier - 3 | DH13: R1013 | DZ13: Id2324 | EA13: =YEAR(DATE(2023,6,8))-YEAR(CW13) -> 24
A14: Id13 | B14: Mr. | C14: Foster | D14: Wade | T14: Id13 | U14: 40.92 | V14: 8.41 | W14: No | X14: No | Y14: No | Z14: 0 | AA14: yes | AV14: Id13 | AW14: 40.92 | AX14: 8.41 | AY14: No | AZ14: No | BA14: No | BB14: No major surgery | BC14: yes | BR14: 40.92 | BS14: {=_xlfn.IFS(BR14<18.5,"UNDER WEIGHT",BR14<=24.9,"NORMAL WEIGHT",BR14<=29.9,"OVER WEIGHT",BR14>=30,"OBESITY")} -> OBESITY | BV14: 8.41 | BW14: {=_xlfn.IFS(BV14<=5.7,"NORMAL",BV14<=6.4,"Prediabetes",BV14>=6.5,"Diabetes")} -> Diabetes | CJ14: Id2323 | CK14: 1999 | CL14: Dec | CM14: 14 | CN14: 0 | CO14: 722.99 | CP14: tier - 3 | CQ14: tier - 1 | CR14: R1013 | CW14: =_xlfn.CONCAT(CM14,"/",CL14,"/",CK14) -> 14/Dec/1999 | CZ14: Id2323 | DA14: 1999 | DB14: Dec | DC14: 14 | DD14: 0 | DE14: 722.99 | DF14: tier - 3 | DG14: tier - 1 | DH14: R1013 | DZ14: Id2323 | EA14: =YEAR(DATE(2023,6,8))-YEAR(CW14) -> 24
A15: Id14 | B15: Mr. | C15: Tenorio | D15: Franklin | T15: Id14 | U15: 40.565 | V15: 7.02 | W15: No | X15: No | Y15: No | Z15: 0 | AA15: yes | AV15: Id14 | AW15: 40.565 | AX15: 7.02 | AY15: No | AZ15: No | BA15: No | BB15: No major surgery | BC15: yes | BR15: 40.565 | BS15: {=_xlfn.IFS(BR15<18.5,"UNDER WEIGHT",BR15<=24.9,"NORMAL WEIGHT",BR15<=29.9,"OVER WEIGHT",BR15>=30,"OBESITY")} -> OBESITY | BV15: 7.02 | BW15: {=_xlfn.IFS(BV15<=5.7,"NORMAL",BV15<=6.4,"Prediabetes",BV15>=6.5,"Diabetes")} -> Diabetes | CJ15: Id2322 | CK15: 2002 | CL15: ? | CM15: 19 | CN15: 0 | CO15: 750 | CP15: tier - 3 | CQ15: tier - 1 | CR15: R1012 | CW15: =_xlfn.CONCAT(CM15,"/",CL15,"/",CK15) -> 19/?/2002 | CZ15: Id2322 | DA15: 2002 | DB15: ? | DC15: 19 | DD15: 0 | DE15: 750 | DF15: tier - 3 | DG15: tier - 1 | DH15: R1012 | DZ15: Id2322 | EA15: =YEAR(DATE(2023,6,8))-YEAR(CW15) -> #VALUE!
A16: Id15 | B16: Ms. | C16: Rios | D16: Leilani M. | T16: Id15 | U16: 36.385 | V16: 7.59 | W16: yes | X16: No | Y16: No | Z16: 2 | AA16: yes | AV16: Id15 | AW16: 36.385 | AX16: 7.59 | AY16: yes | AZ16: No | BA16: No | BB16: 2 | BC16: yes | BR16: 36.385 | BS16: {=_xlfn.IFS(BR16<18.5,"UNDER WEIGHT",BR16<=24.9,"NORMAL WEIGHT",BR16<=29.9,"OVER WEIGHT",BR16>=30,"OBESITY")} -> OBESITY | BV16: 7.59 | BW16: {=_xlfn.IFS(BV16<=5.7,"NORMAL",BV16<=6.4,"Prediabetes",BV16>=6.5,"Diabetes")} -> Diabetes | CJ16: Id2321 | CK16: 1993 | CL16: Aug | CM16: 9 | CN16: 0 | CO16: 760 | CP16: tier - 3 | CQ16: tier - 1 | CR16: R1013 | CW16: =_xlfn.CONCAT(CM16,"/",CL16,"/",CK16) -> 9/Aug/1993 | CZ16: Id2321 | DA16: 1993 | DB16: Aug | DC16: 9 | DD16: 0 | DE16: 760 | DF16: tier - 3 | DG16: tier - 1 | DH16: R1013 | DZ16: Id2321 | EA16: =YEAR(DATE(2023,6,8))-YEAR(CW16) -> 30
A17: Id16 | B17: Mr. | C17: Viau-Dupuis | D17: Philippe | T17: Id16 | U17: 39.9 | V17: 11.32 | W17: No | X17: No | Y17: No | Z17: 0 | AA17: yes | AV17: Id16 | AW17: 39.9 | AX17: 11.32 | AY17: No | AZ17: No | BA17: No | BB17: No major surgery | BC17: yes | BR17: 39.9 | BS17: {=_xlfn.IFS(BR17<18.5,"UNDER WEIGHT",BR17<=24.9,"NORMAL WEIGHT",BR17<=29.9,"OVER WEIGHT",BR17>=30,"OBESITY")} -> OBESITY | BV17: 11.32 | BW17: {=_xlfn.IFS(BV17<=5.7,"NORMAL",BV17<=6.4,"Prediabetes",BV17>=6.5,"Diabetes")} -> Diabetes | CJ17: Id2320 | CK17: 1996 | CL17: Oct | CM17: 22 | CN17: 0 | CO17: 760 | CP17: tier - 3 | CQ17: tier - 3 | CR17: R1013 | CW17: =_xlfn.CONCAT(CM17,"/",CL17,"/",CK17) -> 22/Oct/1996 | CZ17: Id2320 | DA17: 1996 | DB17: Oct | DC17: 22 | DD17: 0 | DE17: 760 | DF17: tier - 3 | DG17: tier - 3 | DH17: R1013 | DZ17: Id2320 | EA17: =YEAR(DATE(2023,6,8))-YEAR(CW17) -> 27
A18: Id17 | B18: Ms. | C18: Cronin | D18: Jennifer A. | T18: Id17 | U18: 33.8 | V18: 7.67 | W18: No | X18: No | Y18: No | Z18: 3 | AA18: yes | AV18: Id17 | AW18: 33.8 | AX18: 7.67 | AY18: No | AZ18: No | BA18: No | BB18: 3 | BC18: yes | BR18: 33.8 | BS18: {=_xlfn.IFS(BR18<18.5,"UNDER WEIGHT",BR18<=24.9,"NORMAL WEIGHT",BR18<=29.9,"OVER WEIGHT",BR18>=30,"OBESITY")} -> OBESITY | BV18: 7.67 | BW18: {=_xlfn.IFS(BV18<=5.7,"NORMAL",BV18<=6.4,"Prediabetes",BV18>=6.5,"Diabetes")} -> Diabetes | CJ18: Id2319 | CK18: 1993 | CL18: Jun | CM18: 28 | CN18: 0 | CO18: 770 | CP18: tier - 3 | CQ18: tier - 3 | CR18: R1013 | CW18: =_xlfn.CONCAT(CM18,"/",CL18,"/",CK18) -> 28/Jun/1993 | CZ18: Id2319 | DA18: 1993 | DB18: Jun | DC18: 28 | DD18: 0 | DE18: 770 | DF18: tier - 3 | DG18: tier - 3 | DH18: R1013 | DZ18: Id2319 | EA18: =YEAR(DATE(2023,6,8))-YEAR(CW18) -> 30
A19: Id18 | B19: Ms. | C19: Noordstar | D19: Christina M. | T19: Id18 | U19: 36.765 | V19: 7.29 | W19: yes | X19: No | Y19: Yes | Z19: 1 | AA19: yes | AV19: Id18 | AW19: 36.765 | AX19: 7.29 | AY19: yes | AZ19: No | BA19: Yes | BB19: 1 | BC19: yes | BR19: 36.765 | BS19: {=_xlfn.IFS(BR19<18.5,"UNDER WEIGHT",BR19<=24.9,"NORMAL WEIGHT",BR19<=29.9,"OVER WEIGHT",BR19>=30,"OBESITY")} -> OBESITY | BV19: 7.29 | BW19: {=_xlfn.IFS(BV19<=5.7,"NORMAL",BV19<=6.4,"Prediabetes",BV19>=6.5,"Diabetes")} -> Diabetes | CJ19: Id2318 | CK19: 1996 | CL19: ? | CM19: 18 | CN19: 0 | CO19: 770.38 | CP19: tier - 3 | CQ19: ? | CR19: R1012 | CW19: =_xlfn.CONCAT(CM19,"/",CL19,"/",CK19) -> 18/?/1996 | CZ19: Id2318 | DA19: 1996 | DB19: ? | DC19: 18 | DD19: 0 | DE19: 770.38 | DF19: tier - 3 | DG19: ? | DH19: R1012 | DZ19: Id2318 | EA19: =YEAR(DATE(2023,6,8))-YEAR(CW19) -> #VALUE!
A20: Id19 | B20: Mr. | C20: Boudalia | D20: Said Sr. | T20: Id19 | U20: 36.955 | V20: 4.72 | W20: yes | X20: No | Y20: No | Z20: 1 | AA20: yes | AV20: Id19 | AW20: 36.955 | AX20: 4.72 | AY20: yes | AZ20: No | BA20: No | BB20: 1 | BC20: yes | BR20: 36.955 | BS20: {=_xlfn.IFS(BR20<18.5,"UNDER WEIGHT",BR20<=24.9,"NORMAL WEIGHT",BR20<=29.9,"OVER WEIGHT",BR20>=30,"OBESITY")} -> OBESITY | BV20: 4.72 | BW20: {=_xlfn.IFS(BV20<=5.7,"NORMAL",BV20<=6.4,"Prediabetes",BV20>=6.5,"Diabetes")} -> NORMAL | CJ20: Id2317 | CK20: 1995 | CL20: Dec | CM20: 7 | CN20: 0 | CO20: 773.54 | CP20: tier - 3 | CQ20: tier - 2 | CR20: R1013 | CW20: =_xlfn.CONCAT(CM20,"/",CL20,"/",CK20) -> 7/Dec/1995 | CZ20: Id2317 | DA20: 1995 | DB20: Dec | DC20: 7 | DD20: 0 | DE20: 773.54 | DF20: tier - 3 | DG20: tier - 2 | DH20: R1013 | DZ20: Id2317 | EA20: =YEAR(DATE(2023,6,8))-YEAR(CW20) -> 28
A21: Id20 | B21: Mr. | C21: Flor | D21: John | T21: Id20 | U21: 42.9 | V21: 11.41 | W21: No | X21: No | Y21: No | Z21: 0 | AA21: yes | AV21: Id20 | AW21: 42.9 | AX21: 11.41 | AY21: No | AZ21: No | BA21: No | BB21: No major surgery | BC21: yes | BR21: 42.9 | BS21: {=_xlfn.IFS(BR21<18.5,"UNDER WEIGHT",BR21<=24.9,"NORMAL WEIGHT",BR21<=29.9,"OVER WEIGHT",BR21>=30,"OBESITY")} -> OBESITY | BV21: 11.41 | BW21: {=_xlfn.IFS(BV21<=5.7,"NORMAL",BV21<=6.4,"Prediabetes",BV21>=6.5,"Diabetes")} -> Diabetes | CJ21: Id2316 | CK21: 2004 | CL21: Oct | CM21: 7 | CN21: 0 | CO21: 830.52 | CP21: tier - 3 | CQ21: tier - 2 | CR21: R1011 | CW21: =_xlfn.CONCAT(CM21,"/",CL21,"/",CK21) -> 7/Oct/2004 | CZ21: Id2316 | DA21: 2004 | DB21: Oct | DC21: 7 | DD21: 0 | DE21: 830.52 | DF21: tier - 3 | DG21: tier - 2 | DH21: R1011 | DZ21: Id2316 | EA21: =YEAR(DATE(2023,6,8))-YEAR(CW21) -> 19
A22: Id21 | B22: Mr. | C22: Fennon | D22: Myles | T22: Id21 | U22: 36.3 | V22: 11.5 | W22: yes | X22: No | Y22: No | Z22: 2 | AA22: yes | AV22: Id21 | AW22: 36.3 | AX22: 11.5 | AY22: yes | AZ22: No | BA22: No | BB22: 2 | BC22: yes | BR22: 36.3 | BS22: {=_xlfn.IFS(BR22<18.5,"UNDER WEIGHT",BR22<=24.9,"NORMAL WEIGHT",BR22<=29.9,"OVER WEIGHT",BR22>=30,"OBESITY")} -> OBESITY | BV22: 11.5 | BW22: {=_xlfn.IFS(BV22<=5.7,"NORMAL",BV22<=6.4,"Prediabetes",BV22>=6.5,"Diabetes")} -> Diabetes | CJ22: Id2315 | CK22: 2000 | CL22: Nov | CM22: 18 | CN22: 0 | CO22: 865.41 | CP22: tier - 3 | CQ22: tier - 1 | CR22: R1013 | CW22: =_xlfn.CONCAT(CM22,"/",CL22,"/",CK22) -> 18/Nov/2000 | CZ22: Id2315 | DA22: 2000 | DB22: Nov | DC22: 18 | DD22: 0 | DE22: 865.41 | DF22: tier - 3 | DG22: tier - 1 | DH22: R1013 | DZ22: Id2315 | EA22: =YEAR(DATE(2023,6,8))-YEAR(CW22) -> 23
A23: Id22 | B23: Ms. | C23: Hribar | D23: Madelyn C | T23: Id22 | U23: 32.2 | V23: 6.22 | W23: yes | X23: No | Y23: No | Z23: 2 | AA23: yes | AV23: Id22 | AW23: 32.2 | AX23: 6.22 | AY23: yes | AZ23: No | BA23: No | BB23: 2 | BC23: yes | BR23: 32.2 | BS23: {=_xlfn.IFS(BR23<18.5,"UNDER WEIGHT",BR23<=24.9,"NORMAL WEIGHT",BR23<=29.9,"OVER WEIGHT",BR23>=30,"OBESITY")} -> OBESITY | BV23: 6.22 | BW23: {=_xlfn.IFS(BV23<=5.7,"NORMAL",BV23<=6.4,"Prediabetes",BV23>=6.5,"Diabetes")} -> Prediabetes | CJ23: Id2314 | CK23: 1993 | CL23: Nov | CM23: 27 | CN23: 0 | CO23: 896.21 | CP23: tier - 3 | CQ23: tier - 1 | CR23: R1013 | CW23: =_xlfn.CONCAT(CM23,"/",CL23,"/",CK23) -> 27/Nov/1993 | CZ23: Id2314 | DA23: 1993 | DB23: Nov | DC23: 27 | DD23: 0 | DE23: 896.21 | DF23: tier - 3 | DG23: tier - 1 | DH23: R1013 | DZ23: Id2314 | EA23: =YEAR(DATE(2023,6,8))-YEAR(CW23) -> 30
A24: Id23 | B24: Ms. | C24: Tassello | D24: Nicole | T24: Id23 | U24: 31.3 | V24: 11.38 | W24: No | X24: No | Y24: No | Z24: 3 | AA24: yes | AV24: Id23 | AW24: 31.3 | AX24: 11.38 | AY24: No | AZ24: No | BA24: No | BB24: 3 | BC24: yes | BR24: 31.3 | BS24: {=_xlfn.IFS(BR24<18.5,"UNDER WEIGHT",BR24<=24.9,"NORMAL WEIGHT",BR24<=29.9,"OVER WEIGHT",BR24>=30,"OBESITY")} -> OBESITY | BV24: 11.38 | BW24: {=_xlfn.IFS(BV24<=5.7,"NORMAL",BV24<=6.4,"Prediabetes",BV24>=6.5,"Diabetes")} -> Diabetes | CJ24: Id2313 | CK24: 1994 | CL24: Oct | CM24: 30 | CN24: 0 | CO24: 915.07 | CP24: tier - 3 | CQ24: tier - 1 | CR24: R1013 | CW24: =_xlfn.CONCAT(CM24,"/",CL24,"/",CK24) -> 30/Oct/1994 | CZ24: Id2313 | DA24: 1994 | DB24: Oct | DC24: 30 | DD24: 0 | DE24: 915.07 | DF24: tier - 3 | DG24: tier - 1 | DH24: R1013 | DZ24: Id2313 | EA24: =YEAR(DATE(2023,6,8))-YEAR(CW24) -> 29
A25: Id24 | B25: Mr. | C25: Mauricette | D25: Eric A. | T25: Id24 | U25: 41.8 | V25: 7.89 | W25: yes | X25: No | Y25: No | Z25: 2 | AA25: yes | AV25: Id24 | AW25: 41.8 | AX25: 7.89 | AY25: yes | AZ25: No | BA25: No | BB25: 2 | BC25: yes | BR25: 41.8 | BS25: {=_xlfn.IFS(BR25<18.5,"UNDER WEIGHT",BR25<=24.9,"NORMAL WEIGHT",BR25<=29.9,"OVER WEIGHT",BR25>=30,"OBESITY")} -> OBESITY | BV25: 7.89 | BW25: {=_xlfn.IFS(BV25<=5.7,"NORMAL",BV25<=6.4,"Prediabetes",BV25>=6.5,"Diabetes")} -> Diabetes | CJ25: Id2312 | CK25: 1995 | CL25: Oct | CM25: 28 | CN25: 0 | CO25: 928.59 | CP25: tier - 3 | CQ25: tier - 1 | CR25: R1013 | CW25: =_xlfn.CONCAT(CM25,"/",CL25,"/",CK25) -> 28/Oct/1995 | CZ25: Id2312 | DA25: 1995 | DB25: Oct | DC25: 28 | DD25: 0 | DE25: 928.59 | DF25: tier - 3 | DG25: tier - 1 | DH25: R1013 | DZ25: Id2312 | EA25: =YEAR(DATE(2023,6,8))-YEAR(CW25) -> 28
A26: Id25 | B26: Mr. | C26: Garcia | D26: Emiliano I. | T26: Id25 | U26: 35.09 | V26: 4.38 | W26: yes | X26: No | Y26: No | Z26: 2 | AA26: yes | AV26: Id25 | AW26: 35.09 | AX26: 4.38 | AY26: yes | AZ26: No | BA26: No | BB26: 2 | BC26: yes | BR26: 35.09 | BS26: {=_xlfn.IFS(BR26<18.5,"UNDER WEIGHT",BR26<=24.9,"NORMAL WEIGHT",BR26<=29.9,"OVER WEIGHT",BR26>=30,"OBESITY")} -> OBESITY | BV26: 4.38 | BW26: {=_xlfn.IFS(BV26<=5.7,"NORMAL",BV26<=6.4,"Prediabetes",BV26>=6.5,"Diabetes")} -> NORMAL | CJ26: Id2311 | CK26: 2001 | CL26: Aug | CM26: 19 | CN26: 0 | CO26: 964.71 | CP26: tier - 3 | CQ26: tier - 2 | CR26: R1013 | CW26: =_xlfn.CONCAT(CM26,"/",CL26,"/",CK26) -> 19/Aug/2001 | CZ26: Id2311 | DA26: 2001 | DB26: Aug | DC26: 19 | DD26: 0 | DE26: 964.71 | DF26: tier - 3 | DG26: tier - 2 | DH26: R1013 | DZ26: Id2311 | EA26: =YEAR(DATE(2023,6,8))-YEAR(CW26) -> 22
A27: Id26 | B27: Mr. | C27: Airoldi | D27: Adam | T27: Id26 | U27: 33.88 | V27: 7.01 | W27: No | X27: No | Y27: No | Z27: 3 | AA27: yes | AV27: Id26 | AW27: 33.88 | AX27: 7.01 | AY27: No | AZ27: No | BA27: No | BB27: 3 | BC27: yes | BR27: 33.88 | BS27: {=_xlfn.IFS(BR27<18.5,"UNDER WEIGHT",BR27<=24.9,"NORMAL WEIGHT",BR27<=29.9,"OVER WEIGHT",BR27>=30,"OBESITY")} -> OBESITY | BV27: 7.01 | BW27: {=_xlfn.IFS(BV27<=5.7,"NORMAL",BV27<=6.4,"Prediabetes",BV27>=6.5,"Diabetes")} -> Diabetes | CJ27: Id2310 | CK27: 1994 | CL27: Nov | CM27: 22 | CN27: 0 | CO27: 1006.65 | CP27: tier - 3 | CQ27: tier - 2 | CR27: R1013 | CW27: =_xlfn.CONCAT(CM27,"/",CL27,"/",CK27) -> 22/Nov/1994 | CZ27: Id2310 | DA27: 1994 | DB27: Nov | DC27: 22 | DD27: 0 | DE27: 1006.65 | DF27: tier - 3 | DG27: tier - 2 | DH27: R1013 | DZ27: Id2310 | EA27: =YEAR(DATE(2023,6,8))-YEAR(CW27) -> 29
A28: Id27 | B28: Mr. | C28: Cater-Cyker | D28: Zach | T28: Id27 | U28: 30.875 | V28: 11.88 | W28: No | X28: No | Y28: No | Z28: 0 | AA28: yes | AV28: Id27 | AW28: 30.875 | AX28: 11.88 | AY28: No | AZ28: No | BA28: No | BB28: No major surgery | BC28: yes | BR28: 30.875 | BS28: {=_xlfn.IFS(BR28<18.5,"UNDER WEIGHT",BR28<=24.9,"NORMAL WEIGHT",BR28<=29.9,"OVER WEIGHT",BR28>=30,"OBESITY")} -> OBESITY | BV28: 11.88 | BW28: {=_xlfn.IFS(BV28<=5.7,"NORMAL",BV28<=6.4,"Prediabetes",BV28>=6.5,"Diabetes")} -> Diabetes | CJ28: Id2309 | CK28: 2000 | CL28: Oct | CM28: 9 | CN28: 0 | CO28: 1012 | CP28: tier - 3 | CQ28: tier - 2 | CR28: R1013 | CW28: =_xlfn.CONCAT(CM28,"/",CL28,"/",CK28) -> 9/Oct/2000 | CZ28: Id2309 | DA28: 2000 | DB28: Oct | DC28: 9 | DD28: 0 | DE28: 1012 | DF28: tier - 3 | DG28: tier - 2 | DH28: R1013 | DZ28: Id2309 | EA28: =YEAR(DATE(2023,6,8))-YEAR(CW28) -> 23
A29: Id28 | B29: Ms. | C29: Hamm | D29: Stephanie W. | T29: Id28 | U29: 36.86 | V29: 5.19 | W29: yes | X29: No | Y29: Yes | Z29: 1 | AA29: yes | AV29: Id28 | AW29: 36.86 | AX29: 5.19 | AY29: yes | AZ29: No | BA29: Yes | BB29: 1 | BC29: yes | BR29: 36.86 | BS29: {=_xlfn.IFS(BR29<18.5,"UNDER WEIGHT",BR29<=24.9,"NORMAL WEIGHT",BR29<=29.9,"OVER WEIGHT",BR29>=30,"OBESITY")} -> OBESITY | BV29: 5.19 | BW29: {=_xlfn.IFS(BV29<=5.7,"NORMAL",BV29<=6.4,"Prediabetes",BV29>=6.5,"Diabetes")} -> NORMAL | CJ29: Id2308 | CK29: 1999 | CL29: Aug | CM29: 5 | CN29: 0 | CO29: 1019 | CP29: tier - 3 | CQ29: tier - 2 | CR29: R1013 | CW29: =_xlfn.CONCAT(CM29,"/",CL29,"/",CK29) -> 5/Aug/1999 | CZ29: Id2308 | DA29: 1999 | DB29: Aug | DC29: 5 | DD29: 0 | DE29: 1019 | DF29: tier - 3 | DG29: tier - 2 | DH29: R1013 | DZ29: Id2308 | EA29: =YEAR(DATE(2023,6,8))-YEAR(CW29) -> 24
A30: Id29 | B30: Mr. | C30: Cox | D30: Stephen | T30: Id29 | U30: 35.86 | V30: 6.74 | W30: yes | X30: No | Y30: No | Z30: 2 | AA30: yes | AV30: Id29 | AW30: 35.86 | AX30: 6.74 | AY30: yes | AZ30: No | BA30: No | BB30: 2 | BC30: yes | BR30: 35.86 | BS30: {=_xlfn.IFS(BR30<18.5,"UNDER WEIGHT",BR30<=24.9,"NORMAL WEIGHT",BR30<=29.9,"OVER WEIGHT",BR30>=30,"OBESITY")} -> OBESITY | BV30: 6.74 | BW30: {=_xlfn.IFS(BV30<=5.7,"NORMAL",BV30<=6.4,"Prediabetes",BV30>=6.5,"Diabetes")} -> Diabetes | CJ30: Id2307 | CK30: 1995 | CL30: Oct | CM30: 5 | CN30: 0 | CO30: 1033.74 | CP30: tier - 3 | CQ30: tier - 1 | CR30: R1013 | CW30: =_xlfn.CONCAT(CM30,"/",CL30,"/",CK30) -> 5/Oct/1995 | CZ30: Id2307 | DA30: 1995 | DB30: Oct | DC30: 5 | DD30: 0 | DE30: 1033.74 | DF30: tier - 3 | DG30: tier - 1 | DH30: R1013 | DZ30: Id2307 | EA30: =YEAR(DATE(2023,6,8))-YEAR(CW30) -> 28
A31: Id30 | B31: Ms. | C31: Sachrajda | D31: Natalie | T31: Id30 | U31: 37.05 | V31: 8.44 | W31: No | X31: No | Y31: No | Z31: 0 | AA31: yes | AV31: Id30 | AW31: 37.05 | AX31: 8.44 | AY31: No | AZ31: No | BA31: No | BB31: No major surgery | BC31: yes | BR31: 37.05 | BS31: {=_xlfn.IFS(BR31<18.5,"UNDER WEIGHT",BR31<=24.9,"NORMAL WEIGHT",BR31<=29.9,"OVER WEIGHT",BR31>=30,"OBESITY")} -> OBESITY | BV31: 8.44 | BW31: {=_xlfn.IFS(BV31<=5.7,"NORMAL",BV31<=6.4,"Prediabetes",BV31>=6.5,"Diabetes")} -> Diabetes | CJ31: Id2306 | CK31: 1994 | CL31: Nov | CM31: 17 | CN31: 0 | CO31: 1044 | CP31: tier - 3 | CQ31: tier - 2 | CR31: R1013 | CW31: =_xlfn.CONCAT(CM31,"/",CL31,"/",CK31) -> 17/Nov/1994 | CZ31: Id2306 | DA31: 1994 | DB31: Nov | DC31: 17 | DD31: 0 | DE31: 1044 | DF31: tier - 3 | DG31: tier - 2 | DH31: R1013 | DZ31: Id2306 | EA31: =YEAR(DATE(2023,6,8))-YEAR(CW31) -> 29
A32: Id31 | B32: Ms. | C32: Gareri | D32: Nicole J. | T32: Id31 | U32: 43.89 | V32: 8.71 | W32: No | X32: No | Y32: No | Z32: 0 | AA32: yes | AV32: Id31 | AW32: 43.89 | AX32: 8.71 | AY32: No | AZ32: No | BA32: No | BB32: No major surgery | BC32: yes | BR32: 43.89 | BS32: {=_xlfn.IFS(BR32<18.5,"UNDER WEIGHT",BR32<=24.9,"NORMAL WEIGHT",BR32<=29.9,"OVER WEIGHT",BR32>=30,"OBESITY")} -> OBESITY | BV32: 8.71 | BW32: {=_xlfn.IFS(BV32<=5.7,"NORMAL",BV32<=6.4,"Prediabetes",BV32>=6.5,"Diabetes")} -> Diabetes | CJ32: Id2305 | CK32: 2002 | CL32: Jul | CM32: 20 | CN32: 0 | CO32: 1047 | CP32: tier - 3 | CQ32: tier - 1 | CR32: R1013 | CW32: =_xlfn.CONCAT(CM32,"/",CL32,"/",CK32) -> 20/Jul/2002 | CZ32: Id2305 | DA32: 2002 | DB32: Jul | DC32: 20 | DD32: 0 | DE32: 1047 | DF32: tier - 3 | DG32: tier - 1 | DH32: R1013 | DZ32: Id2305 | EA32: =YEAR(DATE(2023,6,8))-YEAR(CW32) -> 21
A33: Id32 | B33: Mr. | C33: Welch | D33: Jefferson D | T33: Id32 | U33: 42.35 | V33: 5.08 | W33: yes | X33: No | Y33: No | Z33: 0 | AA33: yes | AV33: Id32 | AW33: 42.35 | AX33: 5.08 | AY33: yes | AZ33: No | BA33: No | BB33: No major surgery | BC33: yes | BR33: 42.35 | BS33: {=_xlfn.IFS(BR33<18.5,"UNDER WEIGHT",BR33<=24.9,"NORMAL WEIGHT",BR33<=29.9,"OVER WEIGHT",BR33>=30,"OBESITY")} -> OBESITY | BV33: 5.08 | BW33: {=_xlfn.IFS(BV33<=5.7,"NORMAL",BV33<=6.4,"Prediabetes",BV33>=6.5,"Diabetes")} -> NORMAL | CJ33: Id2304 | CK33: 2002 | CL33: Jul | CM33: 1 | CN33: 0 | CO33: 1049 | CP33: tier - 3 | CQ33: tier - 2 | CR33: R1012 | CW33: =_xlfn.CONCAT(CM33,"/",CL33,"/",CK33) -> 1/Jul/2002 | CZ33: Id2304 | DA33: 2002 | DB33: Jul | DC33: 1 | DD33: 0 | DE33: 1049 | DF33: tier - 3 | DG33: tier - 2 | DH33: R1012 | DZ33: Id2304 | EA33: =YEAR(DATE(2023,6,8))-YEAR(CW33) -> 21
A34: Id33 | B34: Mr. | C34: Prindiville | D34: Brendan D. | T34: Id33 | U34: 31.35 | V34: 6.86 | W34: No | X34: No | Y34: No | Z34: 0 | AA34: yes | AV34: Id33 | AW34: 31.35 | AX34: 6.86 | AY34: No | AZ34: No | BA34: No | BB34: No major surgery | BC34: yes | BR34: 31.35 | BS34: {=_xlfn.IFS(BR34<18.5,"UNDER WEIGHT",BR34<=24.9,"NORMAL WEIGHT",BR34<=29.9,"OVER WEIGHT",BR34>=30,"OBESITY")} -> OBESITY | BV34: 6.86 | BW34: {=_xlfn.IFS(BV34<=5.7,"NORMAL",BV34<=6.4,"Prediabetes",BV34>=6.5,"Diabetes")} -> Diabetes | CJ34: Id2303 | CK34: 1995 | CL34: Jun | CM34: 1 | CN34: 0 | CO34: 1056 | CP34: tier - 3 | CQ34: tier - 2 | CR34: R1013 | CW34: =_xlfn.CONCAT(CM34,"/",CL34,"/",CK34) -> 1/Jun/1995 | CZ34: Id2303 | DA34: 1995 | DB34: Jun | DC34: 1 | DD34: 0 | DE34: 1056 | DF34: tier - 3 | DG34: tier - 2 | DH34: R1013 | DZ34: Id2303 | EA34: =YEAR(DATE(2023,6,8))-YEAR(CW34) -> 28
A35: Id34 | B35: Ms. | C35: Kincaid | D35: Courtney | T35: Id34 | U35: 47.6 | V35: 5.95 | W35: yes | X35: No | Y35: No | Z35: 0 | AA35: yes | AV35: Id34 | AW35: 47.6 | AX35: 5.95 | AY35: yes | AZ35: No | BA35: No | BB35: No major surgery | BC35: yes | BR35: 47.6 | BS35: {=_xlfn.IFS(BR35<18.5,"UNDER WEIGHT",BR35<=24.9,"NORMAL WEIGHT",BR35<=29.9,"OVER WEIGHT",BR35>=30,"OBESITY")} -> OBESITY | BV35: 5.95 | BW35: {=_xlfn.IFS(BV35<=5.7,"NORMAL",BV35<=6.4,"Prediabetes",BV35>=6.5,"Diabetes")} -> Prediabetes | CJ35: Id2302 | CK35: 1993 | CL35: Sep | CM35: 28 | CN35: 0 | CO35: 1068 | CP35: tier - 3 | CQ35: tier - 1 | CR35: R1013 | CW35: =_xlfn.CONCAT(CM35,"/",CL35,"/",CK35) -> 28/Sep/1993 | CZ35: Id2302 | DA35: 1993 | DB35: Sep | DC35: 28 | DD35: 0 | DE35: 1068 | DF35: tier - 3 | DG35: tier - 1 | DH35: R1013 | DZ35: Id2302 | EA35: =YEAR(DATE(2023,6,8))-YEAR(CW35) -> 30
A36: Id35 | B36: Ms. | C36: Bruestle | D36: Sydney L. | T36: Id35 | U36: 46.2 | V36: 6.09 | W36: No | X36: No | Y36: Yes | Z36: 1 | AA36: yes | AV36: Id35 | AW36: 46.2 | AX36: 6.09 | AY36: No | AZ36: No | BA36: Yes | BB36: 1 | BC36: yes | BR36: 46.2 | BS36: {=_xlfn.IFS(BR36<18.5,"UNDER WEIGHT",BR36<=24.9,"NORMAL WEIGHT",BR36<=29.9,"OVER WEIGHT",BR36>=30,"OBESITY")} -> OBESITY | BV36: 6.09 | BW36: {=_xlfn.IFS(BV36<=5.7,"NORMAL",BV36<=6.4,"Prediabetes",BV36>=6.5,"Diabetes")} -> Prediabetes | CJ36: Id2301 | CK36: 2004 | CL36: Aug | CM36: 24 | CN36: 0 | CO36: 1070 | CP36: tier - 3 | CQ36: tier - 3 | CR36: R1013 | CW36: =_xlfn.CONCAT(CM36,"/",CL36,"/",CK36) -> 24/Aug/2004 | CZ36: Id2301 | DA36: 2004 | DB36: Aug | DC36: 24 | DD36: 0 | DE36: 1070 | DF36: tier - 3 | DG36: tier - 3 | DH36: R1013 | DZ36: Id2301 | EA36: =YEAR(DATE(2023,6,8))-YEAR(CW36) -> 19
A37: Id36 | B37: Mr. | C37: Lachance | D37: Julien | T37: Id36 | U37: 32.015 | V37: 11.75 | W37: No | X37: No | Y37: No | Z37: 0 | AA37: yes | AV37: Id36 | AW37: 32.015 | AX37: 11.75 | AY37: No | AZ37: No | BA37: No | BB37: No major surgery | BC37: yes | BR37: 32.015 | BS37: {=_xlfn.IFS(BR37<18.5,"UNDER WEIGHT",BR37<=24.9,"NORMAL WEIGHT",BR37<=29.9,"OVER WEIGHT",BR37>=30,"OBESITY")} -> OBESITY | BV37: 11.75 | BW37: {=_xlfn.IFS(BV37<=5.7,"NORMAL",BV37<=6.4,"Prediabetes",BV37>=6.5,"Diabetes")} -> Diabetes | CJ37: Id2300 | CK37: 1997 | CL37: Aug | CM37: 13 | CN37: 0 | CO37: 1071 | CP37: tier - 3 | CQ37: tier - 3 | CR37: R1013 | CW37: =_xlfn.CONCAT(CM37,"/",CL37,"/",CK37) -> 13/Aug/1997 | CZ37: Id2300 | DA37: 1997 | DB37: Aug | DC37: 13 | DD37: 0 | DE37: 1071 | DF37: tier - 3 | DG37: tier - 3 | DH37: R1013 | DZ37: Id2300 | EA37: =YEAR(DATE(2023,6,8))-YEAR(CW37) -> 26
A38: Id37 | B38: Mr. | C38: Eason | D38: Ryan M | T38: Id37 | U38: 40.565 | V38: 7.37 | W38: No | X38: No | Y38: No | Z38: 0 | AA38: yes | AV38: Id37 | AW38: 40.565 | AX38: 7.37 | AY38: No | AZ38: No | BA38: No | BB38: No major surgery | BC38: yes | BR38: 40.565 | BS38: {=_xlfn.IFS(BR38<18.5,"UNDER WEIGHT",BR38<=24.9,"NORMAL WEIGHT",BR38<=29.9,"OVER WEIGHT",BR38>=30,"OBESITY")} -> OBESITY | BV38: 7.37 | BW38: {=_xlfn.IFS(BV38<=5.7,"NORMAL",BV38<=6.4,"Prediabetes",BV38>=6.5,"Diabetes")} -> Diabetes | CJ38: Id2299 | CK38: 1998 | CL38: Dec | CM38: 26 | CN38: 0 | CO38: 1082 | CP38: tier - 3 | CQ38: tier - 2 | CR38: R1013 | CW38: =_xlfn.CONCAT(CM38,"/",CL38,"/",CK38) -> 26/Dec/1998 | CZ38: Id2299 | DA38: 1998 | DB38: Dec | DC38: 26 | DD38: 0 | DE38: 1082 | DF38: tier - 3 | DG38: tier - 2 | DH38: R1013 | DZ38: Id2299 | EA38: =YEAR(DATE(2023,6,8))-YEAR(CW38) -> 25
